Workbook

Sheet Feuil3
A3: Étiquettes de lignes | B3: Moyenne de SepalLengthCm
A4: Iris-setosa | B4: 5.006
A5: Iris-versicolor | B5: 5.936
A6: Iris-virginica | B6: 6.588
A7: Total général | B7: 5.8433333

Sheet Feuil4
A3: Étiquettes de lignes | B3: Moyenne de SepalWidthCm
A4: Iris-setosa | B4: 3.418
A5: Iris-versicolor | B5: 2.77
A6: Iris-virginica | B6: 2.974
A7: Total général | B7: 3.054

Sheet Feuil5
A3: Étiquettes de lignes | B3: Nombre de Id
A4: Grande | B4: 87
A5: Moyenne | B5: 13
A6: Petite | B6: 50
A7: Total général | B7: 150

Sheet Feuil6
A3: Nombre de Id | B3: Étiquettes de colonnes
A4: Étiquettes de lignes | B4: Grande | C4: Moyenne | D4: Petite | E4: Total général
A5: Iris-setosa | D5: 50 | E5: 50
A6: Iris-versicolor | B6: 37 | C6: 13 | E6: 50
A7: Iris-virginica | B7: 50 | E7: 50
A8: Total général | B8: 87 | C8: 13 | D8: 50 | E8: 150

Sheet Feuil7
A3: Étiquettes de lignes | B3: Moyenne de PetalLengthCm
A4: Grande | B4: 5.091954
A5: Moyenne | B5: 3.6615385
A6: Petite | B6: 1.464
A7: Total général | B7: 3.7586667

Sheet donnees
A1: Id | B1: SepalLengthCm | C1: SepalWidthCm | D1: PetalLengthCm | E1: PetalWidthCm | F1: Species | G1: size_sepal | H1: size_petal | I1: size_petal_catégorie
A2: 1 | B2: 5.1 | C2: 3.5 | D2: 1.4 | E2: 0.2 | F2: Iris-setosa | G2: =B2*C2 -> 17.85 | H2: =D2*E2 -> 0.28 | I2: =IF(H2<2,"Petite",IF(H2<5,"Moyenne","Grande")) -> Petite
A3: 2 | B3: 4.9 | C3: 3 | D3: 1.4 | E3: 0.2 | F3: Iris-setosa | G3: =B3*C3 -> 14.7 | H3: =D3*E3 -> 0.28 | I3: =IF(H3<2,"Petite",IF(H3<5,"Moyenne","Grande")) -> Petite
A4: 3 | B4: 4.7 | C4: 3.2 | D4: 1.3 | E4: 0.2 | F4: Iris-setosa | G4: =B4*C4 -> 15.04 | H4: =D4*E4 -> 0.26 | I4: =IF(H4<2,"Petite",IF(H4<5,"Moyenne","Grande")) -> Petite
A5: 4 | B5: 4.6 | C5: 3.1 | D5: 1.5 | E5: 0.2 | F5: Iris-setosa | G5: =B5*C5 -> 14.26 | H5: =D5*E5 -> 0.3 | I5: =IF(H5<2,"Petite",IF(H5<5,"Moyenne","Grande")) -> Petite | K5: =CORREL(B2:B151,C2:C151) -> -0.10936925
A6: 5 | B6: 5 | C6: 3.6 | D6: 1.4 | E6: 0.2 | F6: Iris-setosa | G6: =B6*C6 -> 18 | H6: =D6*E6 -> 0.28 | I6: =IF(H6<2,"Petite",IF(H6<5,"Moyenne","Grande")) -> Petite
A7: 6 | B7: 5.4 | C7: 3.9 | D7: 1.7 | E7: 0.4 | F7: Iris-setosa | G7: =B7*C7 -> 21.06 | H7: =D7*E7 -> 0.68 | I7: =IF(H7<2,"Petite",IF(H7<5,"Moyenne","Grande")) -> Petite
A8: 7 | B8: 4.6 | C8: 3.4 | D8: 1.4 | E8: 0.3 | F8: Iris-setosa | G8: =B8*C8 -> 15.64 | H8: =D8*E8 -> 0.42 | I8: =IF(H8<2,"Petite",IF(H8<5,"Moyenne","Grande")) -> Petite
A9: 8 | B9: 5 | C9: 3.4 | D9: 1.5 | E9: 0.2 | F9: Iris-setosa | G9: =B9*C9 -> 17 | H9: =D9*E9 -> 0.3 | I9: =IF(H9<2,"Petite",IF(H9<5,"Moyenne","Grande")) -> Petite
A10: 9 | B10: 4.4 | C10: 2.9 | D10: 1.4 | E10: 0.2 | F10: Iris-setosa | G10: =B10*C10 -> 12.76 | H10: =D10*E10 -> 0.28 | I10: =IF(H10<2,"Petite",IF(H10<5,"Moyenne","Grande")) -> Petite
A11: 10 | B11: 4.9 | C11: 3.1 | D11: 1.5 | E11: 0.1 | F11: Iris-setosa | G11: =B11*C11 -> 15.19 | H11: =D11*E11 -> 0.15 | I11: =IF(H11<2,"Petite",IF(H11<5,"Moyenne","Grande")) -> Petite
A12: 11 | B12: 5.4 | C12: 3.7 | D12: 1.5 | E12: 0.2 | F12: Iris-setosa | G12: =B12*C12 -> 19.98 | H12: =D12*E12 -> 0.3 | I12: =IF(H12<2,"Petite",IF(H12<5,"Moyenne","Grande")) -> Petite
A13: 12 | B13: 4.8 | C13: 3.4 | D13: 1.6 | E13: 0.2 | F13: Iris-setosa | G13: =B13*C13 -> 16.32 | H13: =D13*E13 -> 0.32 | I13: =IF(H13<2,"Petite",IF(H13<5,"Moyenne","Grande")) -> Petite
A14: 13 | B14: 4.8 | C14: 3 | D14: 1.4 | E14: 0.1 | F14: Iris-setosa | G14: =B14*C14 -> 14.4 | H14: =D14*E14 -> 0.14 | I14: =IF(H14<2,"Petite",IF(H14<5,"Moyenne","Grande")) -> Petite
A15: 14 | B15: 4.3 | C15: 3 | D15: 1.1 | E15: 0.1 | F15: Iris-setosa | G15: =B15*C15 -> 12.9 | H15: =D15*E15 -> 0.11 | I15: =IF(H15<2,"Petite",IF(H15<5,"Moyenne","Grande")) -> Petite
A16: 15 | B16: 5.8 | C16: 4 | D16: 1.2 | E16: 0.2 | F16: Iris-setosa | G16: =B16*C16 -> 23.2 | H16: =D16*E16 -> 0.24 | I16: =IF(H16<2,"Petite",IF(H16<5,"Moyenne","Grande")) -> Petite
A17: 16 | B17: 5.7 | C17: 4.4 | D17: 1.5 | E17: 0.4 | F17: Iris-setosa | G17: =B17*C17 -> 25.08 | H17: =D17*E17 -> 0.6 | I17: =IF(H17<2,"Petite",IF(H17<5,"Moyenne","Grande")) -> Petite
... A138: 137 | B138: 6.3 | C138: 3.4 | D138: 5.6 | E138: 2.4 | F138: Iris-virginica | G138: =B138*C138 -> 21.42 | H138: =D138*E138 -> 13.44 | I138: =IF(H138<2,"Petite",IF(H138<5,"Moyenne","Grande")) -> Grande
A139: 138 | B139: 6.4 | C139: 3.1 | D139: 5.5 | E139: 1.8 | F139: Iris-virginica | G139: =B139*C139 -> 19.84 | H139: =D139*E139 -> 9.9 | I139: =IF(H139<2,"Petite",IF(H139<5,"Moyenne","Grande")) -> Grande | M139: =MEDIAN(B2:B151) -> 5.8
A140: 139 | B140: 6 | C140: 3 | D140: 4.8 | E140: 1.8 | F140: Iris-virginica | G140: =B140*C140 -> 18 | H140: =D140*E140 -> 8.64 | I140: =IF(H140<2,"Petite",IF(H140<5,"Moyenne","Grande")) -> Grande
A141: 140 | B141: 6.9 | C141: 3.1 | D141: 5.4 | E141: 2.1 | F141: Iris-virginica | G141: =B141*C141 -> 21.39 | H141: =D141*E141 -> 11.34 | I141: =IF(H141<2,"Petite",IF(H141<5,"Moyenne","Grande")) -> Grande
A142: 141 | B142: 6.7 | C142: 3.1 | D142: 5.6 | E142: 2.4 | F142: Iris-virginica | G142: =B142*C142 -> 20.77 | H142: =D142*E142 -> 13.44 | I142: =IF(H142<2,"Petite",IF(H142<5,"Moyenne","Grande")) -> Grande
A143: 142 | B143: 6.9 | C143: 3.1 | D143: 5.1 | E143: 2.3 | F143: Iris-virginica | G143: =B143*C143 -> 21.39 | H143: =D143*E143 -> 11.73 | I143: =IF(H143<2,"Petite",IF(H143<5,"Moyenne","Grande")) -> Grande
A144: 143 | B144: 5.8 | C144: 2.7 | D144: 5.1 | E144: 1.9 | F144: Iris-virginica | G144: =B144*C144 -> 15.66 | H144: =D144*E144 -> 9.69 | I144: =IF(H144<2,"Petite",IF(H144<5,"Moyenne","Grande")) -> Grande
A145: 144 | B145: 6.8 | C145: 3.2 | D145: 5.9 | E145: 2.3 | F145: Iris-virginica | G145: =B145*C145 -> 21.76 | H145: =D145*E145 -> 13.57 | I145: =IF(H145<2,"Petite",IF(H145<5,"Moyenne","Grande")) -> Grande
A146: 145 | B146: 6.7 | C146: 3.3 | D146: 5.7 | E146: 2.5 | F146: Iris-virginica | G146: =B146*C146 -> 22.11 | H146: =D146*E146 -> 14.25 | I146: =IF(H146<2,"Petite",IF(H146<5,"Moyenne","Grande")) -> Grande
A147: 146 | B147: 6.7 | C147: 3 | D147: 5.2 | E147: 2.3 | F147: Iris-virginica | G147: =B147*C147 -> 20.1 | H147: =D147*E147 -> 11.96 | I147: =IF(H147<2,"Petite",IF(H147<5,"Moyenne","Grande")) -> Grande
A148: 147 | B148: 6.3 | C148: 2.5 | D148: 5 | E148: 1.9 | F148: Iris-virginica | G148: =B148*C148 -> 15.75 | H148: =D148*E148 -> 9.5 | I148: =IF(H148<2,"Petite",IF(H148<5,"Moyenne","Grande")) -> Grande
A149: 148 | B149: 6.5 | C149: 3 | D149: 5.2 | E149: 2 | F149: Iris-virginica | G149: =B149*C149 -> 19.5 | H149: =D149*E149 -> 10.4 | I149: =IF(H149<2,"Petite",IF(H149<5,"Moyenne","Grande")) -> Grande
A150: 149 | B150: 6.2 | C150: 3.4 | D150: 5.4 | E150: 2.3 | F150: Iris-virginica | G150: =B150*C150 -> 21.08 | H150: =D150*E150 -> 12.42 | I150: =IF(H150<2,"Petite",IF(H150<5,"Moyenne","Grande")) -> Grande
A151: 150 | B151: 5.9 | C151: 3 | D151: 5.1 | E151: 1.8 | F151: Iris-virginica | G151: =B151*C151 -> 17.7 | H151: =D151*E151 -> 9.18 | I151: =IF(H151<2,"Petite",IF(H151<5,"Moyenne","Grande")) -> Grande

Sheet analyse
A1: ANALYSE DES DONNEES
A4: Analyse Exploratoire des données
D6: Propriété Générale des données
C7: données Quantitatives
C9: SepallengthCm | D9: SepalwidthCm | E9: PetalLengthCm | F9: PetalWidthCm
B10: Nombre_total | C10: =COUNT(donnees!B2:B151) -> 150 | D10: =COUNT(donnees!C2:C151) -> 150 | E10: =COUNT(donnees!D2:D151) -> 150 | F10: =COUNT(donnees!E2:E151) -> 150
B11: Minimum | C11: =MIN(donnees!B2:B151) -> 4.3 | D11: =MIN(donnees!C2:C151) -> 2 | E11: =MIN(donnees!D2:D151) -> 1 | F11: =MIN(donnees!E2:E151) -> 0.1
B12: Maximum | C12: =MAX(donnees!B2:B151) -> 7.9 | D12: =MAX(donnees!C2:C151) -> 4.4 | E12: =MAX(donnees!D2:D151) -> 6.9 | F12: =MAX(donnees!E2:E151) -> 2.5
B13: Moyenne | C13: =AVERAGE(donnees!B2:B151) -> 5.8433333 | D13: =AVERAGE(donnees!C2:C151) -> 3.054 | E13: =AVERAGE(donnees!D2:D151) -> 3.7586667 | F13: =AVERAGE(donnees!E2:E151) -> 1.1986667
B14: Ecart_type | C14: =AVEDEV(donnees!B2:B151) -> 0.68755556 | D14: =AVEDEV(donnees!C2:C151) -> 0.33309333 | E14: =AVEDEV(donnees!D2:D151) -> 1.56192 | F14: =AVEDEV(donnees!E2:E151) -> 0.65893333
C17: Données Quantitatives
B19: Catégorie | C19: Species | D19: Catégorie | E19: size_petal_catégorie
B20: Nombre_Iris-setosa | C20: =COUNTIF(donnees!F2:F151, "Iris-setosa") -> 50 | D20: nombre_Petite | E20: =COUNTIF(donnees!I2:I151, "Petite") -> 50
B21: Nombre_Iris-versicolor | C21: =COUNTIF(donnees!F2:F151, "Iris-versicolor") -> 50 | D21: Nombre_Moyenne | E21: =COUNTIF(donnees!I2:I151, "Moyenne") -> 13
B22: Nombre_Iris-virginica | C22: =COUNTIF(donnees!F2:F151, "Iris-virginica") -> 50 | D22: Nombre_grande | E22: =COUNTIF(donnees!I2:I151, "grande") -> 87
D28: Visualisation de chaque variable
B86: Objectif : comparer les dimensions moyennes entre espèces
B106: Objectif : savoir combien de fleurs sont dans chaque catégorie. | E106: Voir comment chaque espèce est répartie selon la taille des pétales. | I106: Visualiser la relation entre taille catégorique et longueur réelle.

Sheet Feuil2
B1: Colonne 1
A2: Colonne 1 | B2: 1

Sheet Feuil8
B1: Colonne 1
A2: Colonne 1 | B2: 1

Sheet Analyse_données
B1: ANALYSE DES DONNEES
D3: Analyse des variables Quantitative
E5: Visualisation SepalLengthCm
B7: SepalLengthCm | C7: ni | D7: Ni | E7: fi(%) | F7: Fi(%)
B8: 5.1 | C8: =COUNTIF(donnees!$B$2:$B$151,B8) -> 9 | D8: =C8 -> 9 | E8: =C8/$D$42*100 -> 6 | F8: =E8 -> 6
B9: 4.9 | C9: =COUNTIF(donnees!$B$2:$B$151,B9) -> 6 | D9: =D8+C9 -> 15 | E9: =C9/$D$42*100 -> 4 | F9: =F8+E9 -> 10
B10: 4.7 | C10: =COUNTIF(donnees!$B$2:$B$151,B10) -> 2 | D10: =D9+C10 -> 17 | E10: =C10/$D$42*100 -> 1.3333333 | F10: =F9+E10 -> 11.333333
B11: 4.6 | C11: =COUNTIF(donnees!$B$2:$B$151,B11) -> 4 | D11: =D10+C11 -> 21 | E11: =C11/$D$42*100 -> 2.6666667 | F11: =F10+E11 -> 14
B12: 5 | C12: =COUNTIF(donnees!$B$2:$B$151,B12) -> 10 | D12: =D11+C12 -> 31 | E12: =C12/$D$42*100 -> 6.6666667 | F12: =F11+E12 -> 20.666667
B13: 5.4 | C13: =COUNTIF(donnees!$B$2:$B$151,B13) -> 6 | D13: =D12+C13 -> 37 | E13: =C13/$D$42*100 -> 4 | F13: =F12+E13 -> 24.666667
B14: 4.4 | C14: =COUNTIF(donnees!$B$2:$B$151,B14) -> 3 | D14: =D13+C14 -> 40 | E14: =C14/$D$42*100 -> 2 | F14: =F13+E14 -> 26.666667
B15: 4.8 | C15: =COUNTIF(donnees!$B$2:$B$151,B15) -> 5 | D15: =D14+C15 -> 45 | E15: =C15/$D$42*100 -> 3.3333333 | F15: =F14+E15 -> 30
B16: 4.3 | C16: =COUNTIF(donnees!$B$2:$B$151,B16) -> 1 | D16: =D15+C16 -> 46 | E16: =C16/$D$42*100 -> 0.66666667 | F16: =F15+E16 -> 30.666667
B17: 5.8 | C17: =COUNTIF(donnees!$B$2:$B$151,B17) -> 7 | D17: =D16+C17 -> 53 | E17: =C17/$D$42*100 -> 4.6666667 | F17: =F16+E17 -> 35.333333
B18: 5.7 | C18: =COUNTIF(donnees!$B$2:$B$151,B18) -> 8 | D18: =D17+C18 -> 61 | E18: =C18/$D$42*100 -> 5.3333333 | F18: =F17+E18 -> 40.666667
B19: 5.2 | C19: =COUNTIF(donnees!$B$2:$B$151,B19) -> 4 | D19: =D18+C19 -> 65 | E19: =C19/$D$42*100 -> 2.6666667 | F19: =F18+E19 -> 43.333333
B20: 5.5 | C20: =COUNTIF(donnees!$B$2:$B$151,B20) -> 7 | D20: =D19+C20 -> 72 | E20: =C20/$D$42*100 -> 4.6666667 | F20: =F19+E20 -> 48
... B42: 7.9 | C42: =COUNTIF(donnees!$B$2:$B$151,B42) -> 1 | D42: =D41+C42 -> 150 | E42: =C42/$D$42*100 -> 0.66666667 | F42: =F41+E42 -> 100
C43: =SUM(C8:C42) -> 150 | E43: =SUM(E8:E42) -> 100
N44: =MEDIAN(B8:B42) -> 6
D46: Visualisation de la largeur des sépales
B49: SepalWidthCm | C49: ni | D49: Ni | E49: fi(%) | F49: Fi(%)
B50: 3.5 | C50: =COUNTIF(donnees!$C$2:$C$151,B50) -> 6 | D50: =C50 -> 6 | E50: =C50/$D$72*100 -> 4 | F50: =E50 -> 4
B51: 3 | C51: =COUNTIF(donnees!$C$2:$C$151,B51) -> 26 | D51: =D50+C51 -> 32 | E51: =C51/$D$72*100 -> 17.333333 | F51: =F50+E51 -> 21.333333
B52: 3.2 | C52: =COUNTIF(donnees!$C$2:$C$151,B52) -> 13 | D52: =D51+C52 -> 45 | E52: =C52/$D$72*100 -> 8.6666667 | F52: =F51+E52 -> 30
B53: 3.1 | C53: =COUNTIF(donnees!$C$2:$C$151,B53) -> 12 | D53: =D52+C53 -> 57 | E53: =C53/$D$72*100 -> 8 | F53: =F52+E53 -> 38
B54: 3.6 | C54: =COUNTIF(donnees!$C$2:$C$151,B54) -> 3 | D54: =D53+C54 -> 60 | E54: =C54/$D$72*100 -> 2 | F54: =F53+E54 -> 40
B55: 3.9 | C55: =COUNTIF(donnees!$C$2:$C$151,B55) -> 2 | D55: =D54+C55 -> 62 | E55: =C55/$D$72*100 -> 1.3333333 | F55: =F54+E55 -> 41.333333
B56: 3.4 | C56: =COUNTIF(donnees!$C$2:$C$151,B56) -> 12 | D56: =D55+C56 -> 74 | E56: =C56/$D$72*100 -> 8 | F56: =F55+E56 -> 49.333333
B57: 2.9 | C57: =COUNTIF(donnees!$C$2:$C$151,B57) -> 10 | D57: =D56+C57 -> 84 | E57: =C57/$D$72*100 -> 6.6666667 | F57: =F56+E57 -> 56
B58: 3.7 | C58: =COUNTIF(donnees!$C$2:$C$151,B58) -> 3 | D58: =D57+C58 -> 87 | E58: =C58/$D$72*100 -> 2 | F58: =F57+E58 -> 58
B59: 4 | C59: =COUNTIF(donnees!$C$2:$C$151,B59) -> 1 | D59: =D58+C59 -> 88 | E59: =C59/$D$72*100 -> 0.66666667 | F59: =F58+E59 -> 58.666667
B60: 4.4 | C60: =COUNTIF(donnees!$C$2:$C$151,B60) -> 1 | D60: =D59+C60 -> 89 | E60: =C60/$D$72*100 -> 0.66666667 | F60: =F59+E60 -> 59.333333
B61: 3.8 | C61: =COUNTIF(donnees!$C$2:$C$151,B61) -> 6 | D61: =D60+C61 -> 95 | E61: =C61/$D$72*100 -> 4 | F61: =F60+E61 -> 63.333333
B62: 3.3 | C62: =COUNTIF(donnees!$C$2:$C$151,B62) -> 6 | D62: =D61+C62 -> 101 | E62: =C62/$D$72*100 -> 4 | F62: =F61+E62 -> 67.333333
... B72: 2.6 | C72: =COUNTIF(donnees!$C$2:$C$151,B72) -> 5 | D72: =D71+C72 -> 150 | E72: =C72/$D$72*100 -> 3.3333333 | F72: =F71+E72 -> 100
D83: Longueur des pétalales
B85: PetalLengthCm | C85: ni | D85: Ni | E85: fi(%) | F85: Fi(%)
B86: 1.4 | C86: =COUNTIF(donnees!$D$2:$D$151,B86) -> 12 | D86: =C86 -> 12 | E86: =C86/$D$128*100 -> 8 | F86: =E86 -> 8
B87: 1.3 | C87: =COUNTIF(donnees!$D$2:$D$151,B87) -> 7 | D87: =D86+C87 -> 19 | E87: =C87/$D$128*100 -> 4.6666667 | F87: =F86+E87 -> 12.666667
...

Sheet croisé
